[{"name": "test.test_triple_square.TripleSquare.test_calls", "status": "failed", "message": "7 not found in [4, 10] : Are you sure you called 'triple' the right number of times?", "passed": false, "points": ["p01-06.1"], "backtrace": ["  File \"/home/jukka/anaconda3/lib/python3.7/unittest/case.py\", line 59, in testPartExecutor\n    yield\n", "  File \"/home/jukka/anaconda3/lib/python3.7/unittest/case.py\", line 615, in run\n    testMethod()\n", "  File \"/home/jukka/projects/python/data-analysis/hy-data-analysis-with-python-summer-2019/part01-e06_triple_square/test/test_triple_square.py\", line 50, in test_calls\n    self.call_helper([4, 10])\n", "  File \"/home/jukka/projects/python/data-analysis/hy-data-analysis-with-python-summer-2019/part01-e06_triple_square/test/test_triple_square.py\", line 43, in call_helper\n    msg=\"Are you sure you called 'triple' the right number of times?\")\n", "  File \"/home/jukka/anaconda3/lib/python3.7/unittest/case.py\", line 1106, in assertIn\n    self.fail(self._formatMessage(msg, standardMsg))\n", "  File \"/home/jukka/anaconda3/lib/python3.7/unittest/case.py\", line 680, in fail\n    raise self.failureException(msg)\n"]}, {"name": "test.test_triple_square.TripleSquare.test_calls2", "status": "failed", "message": "7 not found in [4] : Are you sure you called 'triple' the right number of times?", "passed": false, "points": ["p01-06.2"], "backtrace": ["  File \"/home/jukka/anaconda3/lib/python3.7/unittest/case.py\", line 59, in testPartExecutor\n    yield\n", "  File \"/home/jukka/anaconda3/lib/python3.7/unittest/case.py\", line 615, in run\n    testMethod()\n", "  File \"/home/jukka/projects/python/data-analysis/hy-data-analysis-with-python-summer-2019/part01-e06_triple_square/test/test_triple_square.py\", line 55, in test_calls2\n    self.call_helper([4])\n", "  File \"/home/jukka/projects/python/data-analysis/hy-data-analysis-with-python-summer-2019/part01-e06_triple_square/test/test_triple_square.py\", line 43, in call_helper\n    msg=\"Are you sure you called 'triple' the right number of times?\")\n", "  File \"/home/jukka/anaconda3/lib/python3.7/unittest/case.py\", line 1106, in assertIn\n    self.fail(self._formatMessage(msg, standardMsg))\n", "  File \"/home/jukka/anaconda3/lib/python3.7/unittest/case.py\", line 680, in fail\n    raise self.failureException(msg)\n"]}]